Workbook

Sheet Assumptions
A1: Line | B1: 1 | C1: 2 | D1: 3 | E1: 4 | F1: 5 | G1: 6 | H1: 7 | I1: 8 | J1: 9 | K1: 10
A2: beta_profile | B2: 1.25 | C2: 1.25 | D2: 1.25 | E2: 1.25 | F2: 1.25 | G2: 1.22 | H2: 1.19 | I2: 1.16 | J2: 1.13 | K2: 1.1
A3: capex0 | B3: 233 | C3: 233 | D3: 233 | E3: 233 | F3: 233 | G3: 233 | H3: 233 | I3: 233 | J3: 233 | K3: 233
A4: capex_growth | B4: 0.3 | C4: 0.3 | D4: 0.3 | E4: 0.3 | F4: 0.3 | G4: 0.3 | H4: 0.3 | I4: 0.3 | J4: 0.3 | K4: 0.3
A5: capex_growth_profile | B5: 0.3 | C5: 0.3 | D5: 0.3 | E5: 0.3 | F5: 0.3 | G5: 0 | H5: 0 | I5: 0 | J5: 0 | K5: 0
A6: debt_cost_profile | B6: 0.085 | C6: 0.085 | D6: 0.085 | E6: 0.085 | F6: 0.085 | G6: 0.083 | H6: 0.081 | I6: 0.079 | J6: 0.077 | K6: 0.075
A7: debt_weight_profile | B7: 0 | C7: 0 | D7: 0 | E7: 0 | F7: 0 | G7: 0.01 | H7: 0.02 | I7: 0.03 | J7: 0.04 | K7: 0.05
A8: depreciation0 | B8: 298 | C8: 298 | D8: 298 | E8: 298 | F8: 298 | G8: 298 | H8: 298 | I8: 298 | J8: 298 | K8: 298
A9: depreciation_growth_profile | B9: 0.3 | C9: 0.3 | D9: 0.3 | E9: 0.3 | F9: 0.3 | G9: 0.252 | H9: 0.204 | I9: 0.156 | J9: 0.108 | K9: 0.06
A10: high_growth | B10: 0.3 | C10: 0.3 | D10: 0.3 | E10: 0.3 | F10: 0.3 | G10: 0.3 | H10: 0.3 | I10: 0.3 | J10: 0.3 | K10: 0.3
A11: margin_profile | B11: 0.11513461 | C11: 0.16135096 | D11: 0.20756731 | E11: 0.25378365 | F11: 0.3 | G11: 0.29 | H11: 0.28 | I11: 0.27 | J11: 0.26 | K11: 0.25
A12: revenue0 | B12: 12406 | C12: 12406 | D12: 12406 | E12: 12406 | F12: 12406 | G12: 12406 | H12: 12406 | I12: 12406 | J12: 12406 | K12: 12406
... A22: working_capital_ratio | B22: 0.075 | C22: 0.075 | D22: 0.075 | E22: 0.075 | F22: 0.075 | G22: 0.075 | H22: 0.075 | I22: 0.075 | J22: 0.075 | K22: 0.075
A23: valuation.wacc | B23: =Model!B42 -> 0.13375 | C23: =Model!C42 -> 0.13375 | D23: =Model!D42 -> 0.13375 | E23: =Model!E42 -> 0.13375 | F23: =Model!F42 -> 0.13375 | G23: =Model!G42 -> 0.1313102 | H23: =Model!H42 -> 0.1288778 | I23: =Model!I42 -> 0.1264528 | ... K23: =Model!K42 -> 0.121625
A24: valuation.terminal_growth | B24: =Assumptions!B16 -> 0.06 | C24: =Assumptions!C16 -> 0.06 | D24: =Assumptions!D16 -> 0.06 | E24: =Assumptions!E16 -> 0.06 | F24: =Assumptions!F16 -> 0.06 | G24: =Assumptions!G16 -> 0.06 | H24: =Assumptions!H16 -> 0.06 | I24: =Assumptions!I16 -> 0.06 | ... K24: =Assumptions!K16 -> 0.06
A25: valuation.net_cash | B25: -650 | C25: -650 | D25: -650 | E25: -650 | F25: -650 | G25: -650 | H25: -650 | I25: -650 | J25: -650 | K25: -650
A26: valuation.shares | B26: 1500 | C26: 1500 | D26: 1500 | E26: 1500 | F26: 1500 | G26: 1500 | H26: 1500 | I26: 1500 | J26: 1500 | K26: 1500

Sheet Model
A1: Line | B1: 1 | C1: 2 | D1: 3 | E1: 4 | F1: 5 | G1: 6 | H1: 7 | I1: 8 | J1: 9 | K1: 10
A2: after_tax_debt_cost | B2: =(Assumptions!B6*(1-Assumptions!B19)) -> 0.0544 | C2: =(Assumptions!C6*(1-Assumptions!C19)) -> 0.0544 | D2: =(Assumptions!D6*(1-Assumptions!D19)) -> 0.0544 | E2: =(Assumptions!E6*(1-Assumptions!E19)) -> 0.0544 | F2: =(Assumptions!F6*(1-Assumptions!F19)) -> 0.0544 | G2: =(Assumptions!G6*(1-Assumptions!G19)) -> 0.05312 | H2: =(Assumptions!H6*(1-Assumptions!H19)) -> 0.05184 | I2: =(Assumptions!I6*(1-Assumptions!I19)) -> 0.05056 | ... K2: =(Assumptions!K6*(1-Assumptions!K19)) -> 0.048
A3: capex | B3: =(((1-Assumptions!B20)*(Assumptions!B3*B44))+(Assumptions!B20*B39)) -> 302.9 | C3: =(((1-Assumptions!C20)*(Assumptions!B3*C44))+(Assumptions!C20*C39)) -> 393.77 | D3: =(((1-Assumptions!D20)*(Assumptions!B3*D44))+(Assumptions!D20*D39)) -> 511.901 | E3: =(((1-Assumptions!E20)*(Assumptions!B3*E44))+(Assumptions!E20*E39)) -> 665.4713 | F3: =(((1-Assumptions!F20)*(Assumptions!B3*F44))+(Assumptions!F20*F39)) -> 865.11269 | G3: =(((1-Assumptions!G20)*(Assumptions!B3*G44))+(Assumptions!G20*G39)) -> 2573.295 | H3: =(((1-Assumptions!H20)*(Assumptions!B3*H44))+(Assumptions!H20*H39)) -> 4281.4772 | I3: =(((1-Assumptions!I20)*(Assumptions!B3*I44))+(Assumptions!I20*I39)) -> 5989.6595 | J3: =(((1-Assumptions!J20)*(Assumptions!B3*J44))+(Assumptions!J20*J39)) -> 7697.8417 | K3: =(((1-Assumptions!K20)*(Assumptions!B3*K44))+(Assumptions!K20*K39)) -> 9406.024
A4: cost_of_equity | B4: =(Assumptions!B15+(Assumptions!B2*Assumptions!B14)) -> 0.13375 | C4: =(Assumptions!C15+(Assumptions!C2*Assumptions!C14)) -> 0.13375 | D4: =(Assumptions!D15+(Assumptions!D2*Assumptions!D14)) -> 0.13375 | E4: =(Assumptions!E15+(Assumptions!E2*Assumptions!E14)) -> 0.13375 | F4: =(Assumptions!F15+(Assumptions!F2*Assumptions!F14)) -> 0.13375 | G4: =(Assumptions!G15+(Assumptions!G2*Assumptions!G14)) -> 0.1321 | H4: =(Assumptions!H15+(Assumptions!H2*Assumptions!H14)) -> 0.13045 | I4: =(Assumptions!I15+(Assumptions!I2*Assumptions!I14)) -> 0.1288 | ... K4: =(Assumptions!K15+(Assumptions!K2*Assumptions!K14)) -> 0.1255
A5: debt_weight | B5: =Assumptions!B7 -> 0 | C5: =Assumptions!C7 -> 0 | D5: =Assumptions!D7 -> 0 | E5: =Assumptions!E7 -> 0 | F5: =Assumptions!F7 -> 0 | G5: =Assumptions!G7 -> 0.01 | H5: =Assumptions!H7 -> 0.02 | I5: =Assumptions!I7 -> 0.03 | ... K5: =Assumptions!K7 -> 0.05
A6: depreciation | B6: =(Assumptions!B8*B45) -> 387.4 | C6: =(Assumptions!B8*C45) -> 503.62 | D6: =(Assumptions!B8*D45) -> 654.706 | E6: =(Assumptions!B8*E45) -> 851.1178 | F6: =(Assumptions!B8*F45) -> 1106.4531 | G6: =(Assumptions!B8*G45) -> 1385.2793 | H6: =(Assumptions!B8*H45) -> 1667.8763 | I6: =(Assumptions!B8*I45) -> 1928.065 | J6: =(Assumptions!B8*J45) -> 2136.296 | K6: =(Assumptions!B8*K45) -> 2264.4738
A7: depreciation10 | B7: =(B12*(1+B14)) -> 2264.4738 | C7: =(C12*(1+C14)) -> 2264.4738 | D7: =(D12*(1+D14)) -> 2264.4738 | E7: =(E12*(1+E14)) -> 2264.4738 | F7: =(F12*(1+F14)) -> 2264.4738 | G7: =(G12*(1+G14)) -> 2264.4738 | H7: =(H12*(1+H14)) -> 2264.4738 | I7: =(I12*(1+I14)) -> 2264.4738 | ... K7: =(K12*(1+K14)) -> 2264.4738
A8: depreciation5 | B8: =(((((Assumptions!B8*(1+Assumptions!B4))*(1+Assumptions!B4))*(1+Assumptions!B4))*(1+Assumptions!B4))*(1+Assumptions!B4)) -> 1106.4531 | C8: =(((((Assumptions!C8*(1+Assumptions!C4))*(1+Assumptions!C4))*(1+Assumptions!C4))*(1+Assumptions!C4))*(1+Assumptions!C4)) -> 1106.4531 | D8: =(((((Assumptions!D8*(1+Assumptions!D4))*(1+Assumptions!D4))*(1+Assumptions!D4))*(1+Assumptions!D4))*(1+Assumptions!D4)) -> 1106.4531 | E8: =(((((Assumptions!E8*(1+Assumptions!E4))*(1+Assumptions!E4))*(1+Assumptions!E4))*(1+Assumptions!E4))*(1+Assumptions!E4)) -> 1106.4531 | F8: =(((((Assumptions!F8*(1+Assumptions!F4))*(1+Assumptions!F4))*(1+Assumptions!F4))*(1+Assumptions!F4))*(1+Assumptions!F4)) -> 1106.4531 | G8: =(((((Assumptions!G8*(1+Assumptions!G4))*(1+Assumptions!G4))*(1+Assumptions!G4))*(1+Assumptions!G4))*(1+Assumptions!G4)) -> 1106.4531 | H8: =(((((Assumptions!H8*(1+Assumptions!H4))*(1+Assumptions!H4))*(1+Assumptions!H4))*(1+Assumptions!H4))*(1+Assumptions!H4)) -> 1106.4531 | I8: =(((((Assumptions!I8*(1+Assumptions!I4))*(1+Assumptions!I4))*(1+Assumptions!I4))*(1+Assumptions!I4))*(1+Assumptions!I4)) -> 1106.4531 | ... K8: =(((((Assumptions!K8*(1+Assumptions!K4))*(1+Assumptions!K4))*(1+Assumptions!K4))*(1+Assumptions!K4))*(1+Assumptions!K4)) -> 1106.4531
A9: depreciation6 | B9: =(B8*(1+B15)) -> 1385.2793 | C9: =(C8*(1+C15)) -> 1385.2793 | D9: =(D8*(1+D15)) -> 1385.2793 | E9: =(E8*(1+E15)) -> 1385.2793 | F9: =(F8*(1+F15)) -> 1385.2793 | G9: =(G8*(1+G15)) -> 1385.2793 | H9: =(H8*(1+H15)) -> 1385.2793 | I9: =(I8*(1+I15)) -> 1385.2793 | ... K9: =(K8*(1+K15)) -> 1385.2793
A10: depreciation7 | B10: =(B9*(1+B16)) -> 1667.8763 | C10: =(C9*(1+C16)) -> 1667.8763 | D10: =(D9*(1+D16)) -> 1667.8763 | E10: =(E9*(1+E16)) -> 1667.8763 | F10: =(F9*(1+F16)) -> 1667.8763 | G10: =(G9*(1+G16)) -> 1667.8763 | H10: =(H9*(1+H16)) -> 1667.8763 | I10: =(I9*(1+I16)) -> 1667.8763 | ... K10: =(K9*(1+K16)) -> 1667.8763
A11: depreciation8 | B11: =(B10*(1+B17)) -> 1928.065 | C11: =(C10*(1+C17)) -> 1928.065 | D11: =(D10*(1+D17)) -> 1928.065 | E11: =(E10*(1+E17)) -> 1928.065 | F11: =(F10*(1+F17)) -> 1928.065 | G11: =(G10*(1+G17)) -> 1928.065 | H11: =(H10*(1+H17)) -> 1928.065 | I11: =(I10*(1+I17)) -> 1928.065 | ... K11: =(K10*(1+K17)) -> 1928.065
A12: depreciation9 | B12: =(B11*(1+B18)) -> 2136.296 | C12: =(C11*(1+C18)) -> 2136.296 | D12: =(D11*(1+D18)) -> 2136.296 | E12: =(E11*(1+E18)) -> 2136.296 | F12: =(F11*(1+F18)) -> 2136.296 | G12: =(G11*(1+G18)) -> 2136.296 | H12: =(H11*(1+H18)) -> 2136.296 | I12: =(I11*(1+I18)) -> 2136.296 | ... K12: =(K11*(1+K18)) -> 2136.296
A13: depreciation_growth | B13: =Assumptions!B9 -> 0.3 | C13: =Assumptions!C9 -> 0.3 | D13: =Assumptions!D9 -> 0.3 | E13: =Assumptions!E9 -> 0.3 | F13: =Assumptions!F9 -> 0.3 | G13: =Assumptions!G9 -> 0.252 | H13: =Assumptions!H9 -> 0.204 | I13: =Assumptions!I9 -> 0.156 | ... K13: =Assumptions!K9 -> 0.06
A14: depreciation_growth10 | B14: =(B18-B19) -> 0.06 | C14: =(C18-C19) -> 0.06 | D14: =(D18-D19) -> 0.06 | E14: =(E18-E19) -> 0.06 | F14: =(F18-F19) -> 0.06 | G14: =(G18-G19) -> 0.06 | H14: =(H18-H19) -> 0.06 | I14: =(I18-I19) -> 0.06 | ... K14: =(K18-K19) -> 0.06
A15: depreciation_growth6 | B15: =(Assumptions!B4-B19) -> 0.252 | C15: =(Assumptions!C4-C19) -> 0.252 | D15: =(Assumptions!D4-D19) -> 0.252 | E15: =(Assumptions!E4-E19) -> 0.252 | F15: =(Assumptions!F4-F19) -> 0.252 | G15: =(Assumptions!G4-G19) -> 0.252 | H15: =(Assumptions!H4-H19) -> 0.252 | I15: =(Assumptions!I4-I19) -> 0.252 | ... K15: =(Assumptions!K4-K19) -> 0.252
A16: depreciation_growth7 | B16: =(B15-B19) -> 0.204 | C16: =(C15-C19) -> 0.204 | D16: =(D15-D19) -> 0.204 | E16: =(E15-E19) -> 0.204 | F16: =(F15-F19) -> 0.204 | G16: =(G15-G19) -> 0.204 | H16: =(H15-H19) -> 0.204 | I16: =(I15-I19) -> 0.204 | ... K16: =(K15-K19) -> 0.204
A17: depreciation_growth8 | B17: =(B16-B19) -> 0.156 | C17: =(C16-C19) -> 0.156 | D17: =(D16-D19) -> 0.156 | E17: =(E16-E19) -> 0.156 | F17: =(F16-F19) -> 0.156 | G17: =(G16-G19) -> 0.156 | H17: =(H16-H19) -> 0.156 | I17: =(I16-I19) -> 0.156 | ... K17: =(K16-K19) -> 0.156
A18: depreciation_growth9 | B18: =(B17-B19) -> 0.108 | C18: =(C17-C19) -> 0.108 | D18: =(D17-D19) -> 0.108 | E18: =(E17-E19) -> 0.108 | F18: =(F17-F19) -> 0.108 | G18: =(G17-G19) -> 0.108 | H18: =(H17-H19) -> 0.108 | I18: =(I17-I19) -> 0.108 | ... K18: =(K17-K19) -> 0.108
A19: depreciation_step | B19: =((Assumptions!B4-Assumptions!B16)/Assumptions!B21) -> 0.048 | C19: =((Assumptions!C4-Assumptions!C16)/Assumptions!C21) -> 0.048 | D19: =((Assumptions!D4-Assumptions!D16)/Assumptions!D21) -> 0.048 | E19: =((Assumptions!E4-Assumptions!E16)/Assumptions!E21) -> 0.048 | F19: =((Assumptions!F4-Assumptions!F16)/Assumptions!F21) -> 0.048 | G19: =((Assumptions!G4-Assumptions!G16)/Assumptions!G21) -> 0.048 | H19: =((Assumptions!H4-Assumptions!H16)/Assumptions!H21) -> 0.048 | I19: =((Assumptions!I4-Assumptions!I16)/Assumptions!I21) -> 0.048 | ... K19: =((Assumptions!K4-Assumptions!K16)/Assumptions!K21) -> 0.048
A20: discount_factor | B20: =(1*B46) -> 1.13375 | C20: =(1*C46) -> 1.2853891 | D20: =(1*D46) -> 1.4573098 | E20: =(1*E46) -> 1.652225 | F20: =(1*F46) -> 1.8732101 | G20: =(1*G46) -> 2.1191817 | H20: =(1*H46) -> 2.3922972 | I20: =(1*I46) -> 2.6948099 | ... K20: =(1*K46) -> 3.3974708
A21: ebit | B21: =(B25*Assumptions!B11) -> 1856.868 | C21: =(C25*Assumptions!C11) -> 3382.9068 | D21: =(D25*Assumptions!D11) -> 5657.4508 | E21: =(E25*Assumptions!E11) -> 8992.2595 | F21: =(F25*Assumptions!F11) -> 13818.783 | G21: =(G25*Assumptions!G11) -> 16724.412 | H21: =(H25*Assumptions!H11) -> 19441.841 | I21: =(I25*Assumptions!I11) -> 21672.098 | ... K21: =(K25*Assumptions!K11) -> 23568.005
A22: fcff | B22: =(((B23+B6)-B3)-B43) -> 993.76052 | C22: =(((C23+C6)-C3)-C43) -> 1912.0349 | D22: =(((D23+D6)-D3)-D43) -> 3291.8353 | E22: =(((E23+E6)-E3)-E43) -> 5327.433 | F22: =(((F23+F6)-F3)-F43) -> 8288.124 | G22: =(((G23+G6)-G3)-G43) -> 8645.0249 | H22: =(((H23+H6)-H3)-H43) -> 8946.8204 | I22: =(((I23+I6)-I3)-I43) -> 8996.1569 | ... K22: =(((K23+K6)-K3)-K43) -> 7541.7616
A23: nopat | B23: =(B21*(1-Assumptions!B19)) -> 1188.3955 | C23: =(C21*(1-Assumptions!C19)) -> 2165.0604 | D23: =(D21*(1-Assumptions!D19)) -> 3620.7685 | E23: =(E21*(1-Assumptions!E19)) -> 5755.0461 | F23: =(F21*(1-Assumptions!F19)) -> 8844.021 | G23: =(G21*(1-Assumptions!G19)) -> 10703.624 | H23: =(H21*(1-Assumptions!H19)) -> 12442.778 | I23: =(I21*(1-Assumptions!I19)) -> 13870.143 | ... K23: =(K21*(1-Assumptions!K19)) -> 15083.523
A24: pv_fcff | B24: =(B22/B20) -> 876.52527 | C24: =(C22/C20) -> 1487.5145 | D24: =(D22/D20) -> 2258.8438 | E24: =(E22/E20) -> 3224.3991 | F24: =(F22/F20) -> 4424.5565 | G24: =(G22/G20) -> 4079.4165 | H24: =(H22/H20) -> 3739.8448 | I24: =(I22/I20) -> 3338.3271 | ... K24: =(K22/K20) -> 2219.8165
A25: revenue | B25: =(Assumptions!B12*B47) -> 16127.8 | C25: =(Assumptions!B12*C47) -> 20966.14 | D25: =(Assumptions!B12*D47) -> 27255.982 | E25: =(Assumptions!B12*E47) -> 35432.777 | F25: =(Assumptions!B12*F47) -> 46062.61 | G25: =(Assumptions!B12*G47) -> 57670.387 | H25: =(Assumptions!B12*H47) -> 69435.146 | I25: =(Assumptions!B12*I47) -> 80267.029 | J25: =(Assumptions!B12*J47) -> 88935.868 | K25: =(Assumptions!B12*K47) -> 94272.02
A26: revenue10 | B26: =(B31*(1+B33)) -> 94272.02 | C26: =(C31*(1+C33)) -> 94272.02 | D26: =(D31*(1+D33)) -> 94272.02 | E26: =(E31*(1+E33)) -> 94272.02 | F26: =(F31*(1+F33)) -> 94272.02 | G26: =(G31*(1+G33)) -> 94272.02 | H26: =(H31*(1+H33)) -> 94272.02 | I26: =(I31*(1+I33)) -> 94272.02 | ... K26: =(K31*(1+K33)) -> 94272.02
A27: revenue5 | B27: =(((((Assumptions!B12*(1+Assumptions!B10))*(1+Assumptions!B10))*(1+Assumptions!B10))*(1+Assumptions!B10))*(1+Assumptions!B10)) -> 46062.61 | C27: =(((((Assumptions!C12*(1+Assumptions!C10))*(1+Assumptions!C10))*(1+Assumptions!C10))*(1+Assumptions!C10))*(1+Assumptions!C10)) -> 46062.61 | D27: =(((((Assumptions!D12*(1+Assumptions!D10))*(1+Assumptions!D10))*(1+Assumptions!D10))*(1+Assumptions!D10))*(1+Assumptions!D10)) -> 46062.61 | E27: =(((((Assumptions!E12*(1+Assumptions!E10))*(1+Assumptions!E10))*(1+Assumptions!E10))*(1+Assumptions!E10))*(1+Assumptions!E10)) -> 46062.61 | F27: =(((((Assumptions!F12*(1+Assumptions!F10))*(1+Assumptions!F10))*(1+Assumptions!F10))*(1+Assumptions!F10))*(1+Assumptions!F10)) -> 46062.61 | G27: =(((((Assumptions!G12*(1+Assumptions!G10))*(1+Assumptions!G10))*(1+Assumptions!G10))*(1+Assumptions!G10))*(1+Assumptions!G10)) -> 46062.61 | H27: =(((((Assumptions!H12*(1+Assumptions!H10))*(1+Assumptions!H10))*(1+Assumptions!H10))*(1+Assumptions!H10))*(1+Assumptions!H10)) -> 46062.61 | I27: =(((((Assumptions!I12*(1+Assumptions!I10))*(1+Assumptions!I10))*(1+Assumptions!I10))*(1+Assumptions!I10))*(1+Assumptions!I10)) -> 46062.61 | ... K27: =(((((Assumptions!K12*(1+Assumptions!K10))*(1+Assumptions!K10))*(1+Assumptions!K10))*(1+Assumptions!K10))*(1+Assumptions!K10)) -> 46062.61
A28: revenue6 | B28: =(B27*(1+B34)) -> 57670.387 | C28: =(C27*(1+C34)) -> 57670.387 | D28: =(D27*(1+D34)) -> 57670.387 | E28: =(E27*(1+E34)) -> 57670.387 | F28: =(F27*(1+F34)) -> 57670.387 | G28: =(G27*(1+G34)) -> 57670.387 | H28: =(H27*(1+H34)) -> 57670.387 | I28: =(I27*(1+I34)) -> 57670.387 | ... K28: =(K27*(1+K34)) -> 57670.387
A29: revenue7 | B29: =(B28*(1+B35)) -> 69435.146 | C29: =(C28*(1+C35)) -> 69435.146 | D29: =(D28*(1+D35)) -> 69435.146 | E29: =(E28*(1+E35)) -> 69435.146 | F29: =(F28*(1+F35)) -> 69435.146 | G29: =(G28*(1+G35)) -> 69435.146 | H29: =(H28*(1+H35)) -> 69435.146 | I29: =(I28*(1+I35)) -> 69435.146 | ... K29: =(K28*(1+K35)) -> 69435.146
A30: revenue8 | B30: =(B29*(1+B36)) -> 80267.029 | C30: =(C29*(1+C36)) -> 80267.029 | D30: =(D29*(1+D36)) -> 80267.029 | E30: =(E29*(1+E36)) -> 80267.029 | F30: =(F29*(1+F36)) -> 80267.029 | G30: =(G29*(1+G36)) -> 80267.029 | H30: =(H29*(1+H36)) -> 80267.029 | I30: =(I29*(1+I36)) -> 80267.029 | ... K30: =(K29*(1+K36)) -> 80267.029
A31: revenue9 | B31: =(B30*(1+B37)) -> 88935.868 | C31: =(C30*(1+C37)) -> 88935.868 | D31: =(D30*(1+D37)) -> 88935.868 | E31: =(E30*(1+E37)) -> 88935.868 | F31: =(F30*(1+F37)) -> 88935.868 | G31: =(G30*(1+G37)) -> 88935.868 | H31: =(H30*(1+H37)) -> 88935.868 | I31: =(I30*(1+I37)) -> 88935.868 | ... K31: =(K30*(1+K37)) -> 88935.868
A32: revenue_growth | B32: =Assumptions!B13 -> 0.3 | C32: =Assumptions!C13 -> 0.3 | D32: =Assumptions!D13 -> 0.3 | E32: =Assumptions!E13 -> 0.3 | F32: =Assumptions!F13 -> 0.3 | G32: =Assumptions!G13 -> 0.252 | H32: =Assumptions!H13 -> 0.204 | I32: =Assumptions!I13 -> 0.156 | ... K32: =Assumptions!K13 -> 0.06
A33: revenue_growth10 | B33: =(B37-B38) -> 0.06 | C33: =(C37-C38) -> 0.06 | D33: =(D37-D38) -> 0.06 | E33: =(E37-E38) -> 0.06 | F33: =(F37-F38) -> 0.06 | G33: =(G37-G38) -> 0.06 | H33: =(H37-H38) -> 0.06 | I33: =(I37-I38) -> 0.06 | ... K33: =(K37-K38) -> 0.06
A34: revenue_growth6 | B34: =(Assumptions!B10-B38) -> 0.252 | C34: =(Assumptions!C10-C38) -> 0.252 | D34: =(Assumptions!D10-D38) -> 0.252 | E34: =(Assumptions!E10-E38) -> 0.252 | F34: =(Assumptions!F10-F38) -> 0.252 | G34: =(Assumptions!G10-G38) -> 0.252 | H34: =(Assumptions!H10-H38) -> 0.252 | I34: =(Assumptions!I10-I38) -> 0.252 | ... K34: =(Assumptions!K10-K38) -> 0.252
A35: revenue_growth7 | B35: =(B34-B38) -> 0.204 | C35: =(C34-C38) -> 0.204 | D35: =(D34-D38) -> 0.204 | E35: =(E34-E38) -> 0.204 | F35: =(F34-F38) -> 0.204 | G35: =(G34-G38) -> 0.204 | H35: =(H34-H38) -> 0.204 | I35: =(I34-I38) -> 0.204 | ... K35: =(K34-K38) -> 0.204
A36: revenue_growth8 | B36: =(B35-B38) -> 0.156 | C36: =(C35-C38) -> 0.156 | D36: =(D35-D38) -> 0.156 | E36: =(E35-E38) -> 0.156 | F36: =(F35-F38) -> 0.156 | G36: =(G35-G38) -> 0.156 | H36: =(H35-H38) -> 0.156 | I36: =(I35-I38) -> 0.156 | ... K36: =(K35-K38) -> 0.156
A37: revenue_growth9 | B37: =(B36-B38) -> 0.108 | C37: =(C36-C38) -> 0.108 | D37: =(D36-D38) -> 0.108 | E37: =(E36-E38) -> 0.108 | F37: =(F36-F38) -> 0.108 | G37: =(G36-G38) -> 0.108 | H37: =(H36-H38) -> 0.108 | I37: =(I36-I38) -> 0.108 | ... K37: =(K36-K38) -> 0.108
A38: revenue_step | B38: =((Assumptions!B10-Assumptions!B16)/Assumptions!B21) -> 0.048 | C38: =((Assumptions!C10-Assumptions!C16)/Assumptions!C21) -> 0.048 | D38: =((Assumptions!D10-Assumptions!D16)/Assumptions!D21) -> 0.048 | E38: =((Assumptions!E10-Assumptions!E16)/Assumptions!E21) -> 0.048 | F38: =((Assumptions!F10-Assumptions!F16)/Assumptions!F21) -> 0.048 | G38: =((Assumptions!G10-Assumptions!G16)/Assumptions!G21) -> 0.048 | H38: =((Assumptions!H10-Assumptions!H16)/Assumptions!H21) -> 0.048 | I38: =((Assumptions!I10-Assumptions!I16)/Assumptions!I21) -> 0.048 | ... K38: =((Assumptions!K10-Assumptions!K16)/Assumptions!K21) -> 0.048
A39: terminal_capex | B39: =((((B40*Assumptions!B16)/Assumptions!B18)-B41)+B7) -> 9406.024 | C39: =((((C40*Assumptions!C16)/Assumptions!C18)-C41)+C7) -> 9406.024 | D39: =((((D40*Assumptions!D16)/Assumptions!D18)-D41)+D7) -> 9406.024 | E39: =((((E40*Assumptions!E16)/Assumptions!E18)-E41)+E7) -> 9406.024 | F39: =((((F40*Assumptions!F16)/Assumptions!F18)-F41)+F7) -> 9406.024 | G39: =((((G40*Assumptions!G16)/Assumptions!G18)-G41)+G7) -> 9406.024 | H39: =((((H40*Assumptions!H16)/Assumptions!H18)-H41)+H7) -> 9406.024 | I39: =((((I40*Assumptions!I16)/Assumptions!I18)-I41)+I7) -> 9406.024 | ... K39: =((((K40*Assumptions!K16)/Assumptions!K18)-K41)+K7) -> 9406.024
A40: terminal_nopat | B40: =((B26*Assumptions!B17)*(1-Assumptions!B19)) -> 15083.523 | C40: =((C26*Assumptions!C17)*(1-Assumptions!C19)) -> 15083.523 | D40: =((D26*Assumptions!D17)*(1-Assumptions!D19)) -> 15083.523 | E40: =((E26*Assumptions!E17)*(1-Assumptions!E19)) -> 15083.523 | F40: =((F26*Assumptions!F17)*(1-Assumptions!F19)) -> 15083.523 | G40: =((G26*Assumptions!G17)*(1-Assumptions!G19)) -> 15083.523 | H40: =((H26*Assumptions!H17)*(1-Assumptions!H19)) -> 15083.523 | I40: =((I26*Assumptions!I17)*(1-Assumptions!I19)) -> 15083.523 | ... K40: =((K26*Assumptions!K17)*(1-Assumptions!K19)) -> 15083.523
...

Sheet DCF
A1: Line | B1: 1 | C1: 2 | D1: 3 | E1: 4 | F1: 5 | G1: 6 | H1: 7 | I1: 8 | J1: 9 | K1: 10
A2: FCF | B2: =Model!B22 -> 993.76052 | C2: =Model!C22 -> 1912.0349 | D2: =Model!D22 -> 3291.8353 | E2: =Model!E22 -> 5327.433 | F2: =Model!F22 -> 8288.124 | G2: =Model!G22 -> 8645.0249 | H2: =Model!H22 -> 8946.8204 | I2: =Model!I22 -> 8996.1569 | ... K2: =Model!K22 -> 7541.7616
A3: WACC | B3: =Assumptions!B23 -> 0.13375 | C3: =Assumptions!C23 -> 0.13375 | D3: =Assumptions!D23 -> 0.13375 | E3: =Assumptions!E23 -> 0.13375 | F3: =Assumptions!F23 -> 0.13375 | G3: =Assumptions!G23 -> 0.1313102 | H3: =Assumptions!H23 -> 0.1288778 | I3: =Assumptions!I23 -> 0.1264528 | ... K3: =Assumptions!K23 -> 0.121625
A4: Discount factor | B4: =1*(1+B3) -> 1.13375 | C4: =B4*(1+C3) -> 1.2853891 | D4: =C4*(1+D3) -> 1.4573098 | E4: =D4*(1+E3) -> 1.652225 | F4: =E4*(1+F3) -> 1.8732101 | G4: =F4*(1+G3) -> 2.1191817 | H4: =G4*(1+H3) -> 2.3922972 | I4: =H4*(1+I3) -> 2.6948099 | J4: =I4*(1+J3) -> 3.0290612 | K4: =J4*(1+K3) -> 3.3974708
A5: Present value | B5: =B2/B4 -> 876.52527 | C5: =C2/C4 -> 1487.5145 | D5: =D2/D4 -> 2258.8438 | E5: =E2/E4 -> 3224.3991 | F5: =F2/F4 -> 4424.5565 | G5: =G2/G4 -> 4079.4165 | H5: =H2/H4 -> 3739.8448 | I5: =I2/I4 -> 3338.3271 | ... K5: =K2/K4 -> 2219.8165
A7: Terminal value | B7: =K2*(1+Assumptions!K24)/(K3-Assumptions!K24) -> 129724.42
A8: Terminal present value | B8: =B7/K4 -> 38182.645
A9: Enterprise value | B9: =SUM(B5:K5)+B8 -> 66666.833
A10: Net cash | B10: =Assumptions!B25 -> -650
A11: Equity value | B11: =B9+B10 -> 66016.833
A12: Shares | B12: =Assumptions!B26 -> 1500
A13: Per-share value | B13: =B11/B12 -> 44.011222
A14: Terminal weight | B14: =B8/B9 -> 0.57273824

Sheet Actuals
A1: period | B1: line | C1: value
